<?xml version="1.0"?>
<robot xmlns:xacro="http://www.ros.org/wiki/xacro" name="mobile_robot">
  <xacro:macro name="default_inertial" params="mass">
    <inertial>
      <mass value="${mass}"/>
      <inertia ixx="1.0" ixy="0.0" ixz="0.0" iyy="1.0" iyz="0.0" izz="1.0"/>
    </inertial>
  </xacro:macro>
  <xacro:macro name="default_inertial" params="mass">
    <inertial>
      <mass value="${mass}"/>
      <inertia ixx="1.0" ixy="0.0" ixz="0.0" iyy="1.0" iyz="0.0" izz="1.0"/>
    </inertial>
  </xacro:macro>

  <xacro:macro name="wheel" params="name x y">
    <link name="${name}">
      <visual>
        <origin xyz="0 0 0" rpy="${pi/2} 0 0"/>
        <geometry>
          <cylinder length="0.04" radius="0.1"/>
        </geometry>
      </visual>
      <collision>
        <origin xyz="0 0 0" rpy="${pi/2} 0 0"/>
        <geometry>
          <cylinder length="0.04" radius="0.1"/>
        </geometry>
      </collision>
      <xacro:default_inertial mass="0.6"/>
    </link>

    <joint name="base_link_${name}" type="continuous">
      <origin xyz="${y*0.25} ${x*0.25} 0" rpy="0 0 0"/>
      <axis rpy="0 0 0" xyz="0 1 0"/>
      <parent link="base_link"/>
      <child link="${name}"/>
    </joint>

    <transmission name="base_link_${name}_wheel_trans">
      <type>transmission_interface/SimpleTransmission</type>
      <actuator name="base_link_${name}_wheel_motor">
        <mechanicalReduction>1</mechanicalReduction>
      </actuator>
      <joint name="base_link_${name}">
        <hardwareInterface>hardware_interface/VelocityJointInterface</hardwareInterface>
      </joint>
    </transmission>
  </xacro:macro>

  <link name="base_link">
    <visual>
      <origin xyz="0 0 0" rpy="0 0 0"/>
      <geometry>
        <box size="0.6 0.4 0.10"/>
      </geometry>
      <material name="acrylic">
        <color rgba="1 1 1 0.8"/>
      </material>
    </visual>
    <collision>
      <origin xyz="0 0 0" rpy="0 0 0"/>
      <geometry>
        <box size="0.6 0.4 0.10"/>
      </geometry>
    </collision>
    <xacro:default_inertial mass="20"/>
  </link>

  <xacro:wheel name="wh_left_back" x="1" y="-1"/>
  <xacro:wheel name="wh_right_back" x="-1" y="-1"/>
  <xacro:wheel name="wh_left_front" x="1" y="1"/>
  <xacro:wheel name="wh_right_front" x="-1" y="1"/>

  <!-- =================== Kinect ==================== -->
  <link name="kinect_link">
    <visual>
      <origin xyz="0 0 0" rpy="0 0 0"/>
      <geometry>
        <mesh filename="package://mobile_robot_description/meshes/kinect.stl" scale="0.01 0.01 0.01"/>
      </geometry>
      <material name="kinect">
        <color rgba="1 0.9 0.9 1"/>
      </material>
    </visual>
    <collision>
      <origin xyz="0 0 0" rpy="0 0 0"/>
      <geometry>
        <box size="0.28 0.07 0.08"/>
      </geometry>
    </collision>
    <xacro:default_inertial mass="0.2"/>
  </link>

  <joint name="base_link_kinect_link" type="fixed">
    <origin xyz="0.265 0 0.087" rpy="0 0 ${pi/2}"/>
    <parent link="base_link"/>
    <child link="kinect_link"/>
  </joint>

  <!-- =================== Gazebo - Kinect ==================== -->
  <link name="gz_kinect_link">
    <visual>
      <origin xyz="0 0 0" rpy="0 0 0"/>
      <geometry>
        <sphere radius="0.05"/>
      </geometry>
      <material name="kinect">
        <color rgba="1 0.9 0.9 1"/>
      </material>
    </visual>
    <collision>
      <origin xyz="0 0 0" rpy="0 0 0"/>
      <geometry>
        <sphere radius="0.05"/>
      </geometry>
    </collision>
    <xacro:default_inertial mass="0.2"/>
  </link>

  <joint name="kinect_link_gz_kinect_link" type="fixed">
    <origin xyz="0 0 0" rpy="0 0 -${pi/2}"/>
    <parent link="kinect_link"/>
    <child link="gz_kinect_link"/>
  </joint>

  <gazebo reference="gz_kinect_link">
    <sensor type="depth" name="kinect">
      <pose>0 0 0 0 0 0</pose>
      <always_on>1</always_on>
      <visualize>true</visualize>

      <camera>
        <horizontal_fov>1.047</horizontal_fov>
        <image>
          <width>640</width>
          <height>480</height>
          <format>R8G8B8</format>
        </image>
        <depth_camera></depth_camera>
        <clip>
          <near>0.1</near>
          <far>100</far>
        </clip>

        <noise>
          <type>gaussian</type>
          <mean>0.0</mean>
          <stddev>0.7</stddev>
        </noise>
      </camera>

      <plugin name="camera_controller" filename="libgazebo_ros_openni_kinect.so">
        <!-- <baseline>0.2</baseline> -->
        <alwaysOn>true</alwaysOn>

        <updateRate>10.0</updateRate>
        <cameraName>kinect_sensor</cameraName>
        <frameName>gz_kinect_link</frameName>

        <imageTopicName>/mobile_robot/rgb/image_raw</imageTopicName>
        <depthImageTopicName>/mobile_robot/depth/image_raw</depthImageTopicName>
        <pointCloudTopicName>/mobile_robot/depth/points</pointCloudTopicName>

        <cameraInfoTopicName>/mobile_robot/rgb/camera_info</cameraInfoTopicName>
        <depthImageInfoTopicName>/mobile_robot/depth/camera_info</depthImageInfoTopicName>

        <pointCloudCutoff>0.4</pointCloudCutoff>
        <hackBaseline>0.07</hackBaseline>
        <distortionK1>0.001</distortionK1>
        <distortionK2>0.001</distortionK2>
        <distortionK3>0.001</distortionK3>
        <distortionT1>0.001</distortionT1>
        <distortionT2>0.001</distortionT2>
        <CxPrime>0</CxPrime>
        <Cx>0</Cx>
        <Cy>0</Cy>
        <focalLength>0</focalLength>
      </plugin>
    </sensor>
  </gazebo>

  <!-- =================== Gazebo ==================== -->
  <gazebo>
    <plugin name="gazebo_ros_control" filename="libgazebo_ros_control.so">
      <robotNamespace>/</robotNamespace>
    </plugin>
  </gazebo>
</robot>
