<?xml version="1.0"?>
<robot xmlns:xacro="http://www.ros.org/wiki/xacro" name="mobile_robot">
  <xacro:macro name="wheel" params="name x y">
    <link name="${name}">
      <visual>
        <origin xyz="0 0 0" rpy="${pi/2} 0 0"/>
        <geometry>
          <cylinder length="0.04" radius="0.1"/>
        </geometry>
      </visual>
      <collision>
        <origin xyz="0 0 0" rpy="${pi/2} 0 0"/>
        <geometry>
          <cylinder length="0.04" radius="0.1"/>
        </geometry>
      </collision>
    </link>
    <joint name="base_link_${name}" type="continuous">
      <origin xyz="${y*0.25} ${x*0.25} 0" rpy="0 0 0"/>
      <axis rpy="0 0 0" xyz="0 1 0"/>
      <parent link="base_link"/>
      <child link="${name}"/>
    </joint>
  </xacro:macro>

  <link name="base_link">
    <visual>
      <origin xyz="0 0 0" rpy="0 0 0"/>
      <geometry>
        <box size="0.6 0.4 0.10"/>
      </geometry>
      <material name="acrylic">
        <color rgba="1 1 1 0.8"/>
      </material>
    </visual>
    <collision>
      <origin xyz="0 0 0" rpy="0 0 0"/>
      <geometry>
        <box size="0.6 0.4 0.10"/>
      </geometry>
    </collision>
  </link>

  <xacro:wheel name="wh_left_back" x="1" y="-1"/>
  <xacro:wheel name="wh_right_back" x="-1" y="-1"/>
  <xacro:wheel name="wh_left_front" x="1" y="1"/>
  <xacro:wheel name="wh_right_front" x="-1" y="1"/>
</robot>
